<?xml version="1.0" ?>
<sdf version="1.9">
  <model name="catamaran">
  
    <link name="base_link">
      <visual name="visual">
        <geometry>
          <mesh>
            <uri>package://catamaran_description/models/catamaran/mesh/catamaran.dae</uri>
            <scale>1 1 1</scale>
          </mesh>
        </geometry>
        <material>
          <script>
            <uri>file://media/materials/scripts/gazebo.material</uri>
            <name>Gazebo/Red</name>
          </script>
        </material>
      </visual>
      
      <collision name="collision">
        <geometry>
          <mesh>
            <uri>package://catamaran_description/models/catamaran/mesh/catamaran.dae</uri>
            <scale>1 1 1</scale>
          </mesh>
        </geometry>
      </collision>
      
      <inertial>
        <mass>180</mass> <!-- kg -->
        <inertia>
          <ixx>120</ixx>
          <iyy>393</iyy>
          <izz>446</izz>
        </inertia>
      </inertial>
    </link>
    
    <!-- Buoyancy plugin -->
    <plugin name="vrx::PolyhedraBuoyancyDrag"
            filename="libPolyhedraBuoyancyDrag.so">
      <fluid_density>1000</fluid_density>
      <fluid_level>0.0</fluid_level>
      <linear_drag>120.0</linear_drag>
      <angular_drag>20.0</angular_drag>
      <buoyancy name="collision_outer">
        <link_name>base_link</link_name>
        <pose>0 0 0 0 0 0</pose>
        <geometry>
          <box>
            <size>6 6 1</size>
          </box>
        </geometry>
      </buoyancy>
      <wavefield>
        <topic>/vrx/wavefield/parameters</topic>
      </wavefield>
    </plugin>

    <enable_wind>true</enable_wind>

    <!-- Thrusters left
    **********************
    **********************
    **********************
    **********************
    -->
    <joint name='catamaran/left_chassis_engine_joint' type='fixed'>
      <pose relative_to='base_link'>-2.9 -3.15 -0.2 0 0 1.57</pose>
      <parent>base_link</parent>
      <child>catamaran/left_engine_link</child>
      <axis>
        <xyz>0 0 1</xyz>
        <limit>
          <lower>-3.1415926535897931</lower>
          <upper>3.1415926535897931</upper>
          <effort>10</effort>
          <velocity>10</velocity>
        </limit>
        <dynamics>
          <spring_reference>0</spring_reference>
          <spring_stiffness>0</spring_stiffness>
        </dynamics>
      </axis>
    </joint>
    <link name='catamaran/left_engine_link'>
      <pose relative_to='catamaran/left_chassis_engine_joint'>0 0 0 0 0 0</pose>
      <inertial>
        <pose>0 0 0 0 0 0</pose>
        <mass>15</mass>
        <inertia>
          <ixx>0.88925</ixx>
          <ixy>0</ixy>
          <ixz>0</ixz>
          <iyy>0.911125</iyy>
          <iyz>0</iyz>
          <izz>0.078125</izz>
        </inertia>
      </inertial>
      <collision name='catamaran/left_engine_link_fixed_joint_lump__left_engine_vertical_axis_collision_collision'>
        <pose>-0.16 0 -0.24 0 0 0</pose>
        <geometry>
          <box>
            <size>0.2 0.15 0.83</size>
          </box>
        </geometry>
      </collision>
      <collision name='catamaran/left_engine_link_fixed_joint_lump__left_engine_rear_end_collision_collision_1'>
        <pose>-0.34 0 0.12 0 0 0</pose>
        <geometry>
          <box>
            <size>0.12 0.15 0.12</size>
          </box>
        </geometry>
      </collision>
      <visual name='catamaran/left_engine_link_visual'>
        <pose>0 0 0 0 0 0</pose>
        <geometry>
          <mesh>
            <scale>1 1 1</scale>
            <uri>model://motor/engine/mesh/engine.dae</uri>
          </mesh>
        </geometry>
      </visual>
    </link>
    <joint name='catamaran/left_engine_propeller_joint' type='revolute'>
      <pose relative_to='catamaran/left_engine_link'>-0.278156 0 -0.509371 0 0 0</pose>
      <parent>catamaran/left_engine_link</parent>
      <child>catamaran/left_propeller_link</child>
      <axis>
        <xyz>1 0 0</xyz>
        <limit>
          <effort>100</effort>
          <velocity>100</velocity>
          <lower>-10000</lower>
          <upper>10000</upper>
        </limit>
        <dynamics>
          <damping>0.05</damping>
          <friction>0.05</friction>
          <spring_reference>0</spring_reference>
          <spring_stiffness>0</spring_stiffness>
        </dynamics>
      </axis>
    </joint>
    <link name='catamaran/left_propeller_link'>
      <pose relative_to='catamaran/left_engine_propeller_joint'>0 0 0 0 0 0</pose>
      <inertial>
        <pose>0 0 0 0 0 0</pose>
        <mass>0.5</mass>
        <inertia>
          <ixx>0.008545</ixx>
          <ixy>0</ixy>
          <ixz>0</ixz>
          <iyy>0.008545</iyy>
          <iyz>0</iyz>
          <izz>0.0144</izz>
        </inertia>
      </inertial>
      <collision name='catamaran/left_propeller_link_fixed_joint_lump__left_propeller_collision_collision'>
        <pose>-0.08 0 0 0 1.570796326794897 0</pose>
        <geometry>
          <cylinder>
            <length>0.18</length>
            <radius>0.24</radius>
          </cylinder>
        </geometry>
      </collision>
      <visual name='catamaran/left_propeller_link_visual'>
        <pose>0 0 0 0 0 0</pose>
        <geometry>
          <mesh>
            <scale>1 1 1</scale>
            <uri>model://motor/propeller/mesh/propeller.dae</uri>
          </mesh>
        </geometry>
      </visual>
    </link>


    <!-- Thruster left -->
    <plugin name='gz::sim::systems::Thruster' filename='gz-sim-thruster-system'>
      <joint_name>catamaran/left_engine_propeller_joint</joint_name>
      <thrust_coefficient>0.004422</thrust_coefficient>
      <thrust_direction>0 1 0</thrust_direction>
      <fluid_density>1000</fluid_density>
      <propeller_diameter>0.2</propeller_diameter>
      <velocity_control>true</velocity_control>
      <max_thrust_cmd>1000</max_thrust_cmd>
      <!-- Naming for thrust topics. Results in:
            /catamaran/thrusters/rear_left
            /catamaran/thrusters/rear_left/ang_vel
      -->
      <namespace>catamaran</namespace>
      <topic>thrusters/rear_left</topic>
      <name>rear_left</name>
    </plugin>

    <!-- Thrusters right
    **********************
    **********************
    **********************
    **********************
    -->
    <joint name='catamaran/right_chassis_engine_joint' type='fixed'>
      <pose relative_to='base_link'>2.9 -3.15 -0.2 0 0 1.57</pose>
      <parent>base_link</parent>
      <child>catamaran/right_engine_link</child>
      <axis>
        <xyz>0 0 1</xyz>
        <limit>
          <lower>-3.1415926535897931</lower>
          <upper>3.1415926535897931</upper>
          <effort>10</effort>
          <velocity>10</velocity>
        </limit>
        <dynamics>
          <spring_reference>0</spring_reference>
          <spring_stiffness>0</spring_stiffness>
        </dynamics>
      </axis>
    </joint>
    <link name='catamaran/right_engine_link'>
      <pose relative_to='catamaran/right_chassis_engine_joint'>0 0 0 0 0 0</pose>
      <inertial>
        <pose>0 0 0 0 0 0</pose>
        <mass>15</mass>
        <inertia>
          <ixx>0.88925</ixx>
          <ixy>0</ixy>
          <ixz>0</ixz>
          <iyy>0.911125</iyy>
          <iyz>0</iyz>
          <izz>0.078125</izz>
        </inertia>
      </inertial>
      <collision name='catamaran/right_engine_link_fixed_joint_lump__right_engine_vertical_axis_collision_collision'>
        <pose>-0.16 0 -0.24 0 0 0</pose>
        <geometry>
          <box>
            <size>0.2 0.15 0.83</size>
          </box>
        </geometry>
      </collision>
      <collision name='catamaran/right_engine_link_fixed_joint_lump__right_engine_rear_end_collision_collision_1'>
        <pose>-0.34 0 0.12 0 0 0</pose>
        <geometry>
          <box>
            <size>0.12 0.15 0.12</size>
          </box>
        </geometry>
      </collision>
      <visual name='catamaran/right_engine_link_visual'>
        <pose>0 0 0 0 0 0</pose>
        <geometry>
          <mesh>
            <scale>1 1 1</scale>
            <uri>model://motor/engine/mesh/engine.dae</uri>
          </mesh>
        </geometry>
      </visual>
    </link>
    <joint name='catamaran/right_engine_propeller_joint' type='revolute'>
      <pose relative_to='catamaran/right_engine_link'>-0.278156 0 -0.509371 0 0 0</pose>
      <parent>catamaran/right_engine_link</parent>
      <child>catamaran/right_propeller_link</child>
      <axis>
        <xyz>1 0 0</xyz>
        <limit>
          <effort>100</effort>
          <velocity>100</velocity>
          <lower>-10000</lower>
          <upper>10000</upper>
        </limit>
        <dynamics>
          <damping>0.05</damping>
          <friction>0.05</friction>
          <spring_reference>0</spring_reference>
          <spring_stiffness>0</spring_stiffness>
        </dynamics>
      </axis>
    </joint>
    <link name='catamaran/right_propeller_link'>
      <pose relative_to='catamaran/right_engine_propeller_joint'>0 0 0 0 0 0</pose>
      <inertial>
        <pose>0 0 0 0 0 0</pose>
        <mass>0.5</mass>
        <inertia>
          <ixx>0.008545</ixx>
          <ixy>0</ixy>
          <ixz>0</ixz>
          <iyy>0.008545</iyy>
          <iyz>0</iyz>
          <izz>0.0144</izz>
        </inertia>
      </inertial>
      <collision name='catamaran/right_propeller_link_fixed_joint_lump__right_propeller_collision_collision'>
        <pose>-0.08 0 0 0 1.570796326794897 0</pose>
        <geometry>
          <cylinder>
            <length>0.18</length>
            <radius>0.24</radius>
          </cylinder>
        </geometry>
      </collision>
      <visual name='catamaran/right_propeller_link_visual'>
        <pose>0 0 0 0 0 0</pose>
        <geometry>
          <mesh>
            <scale>1 1 1</scale>
            <uri>model://motor/propeller/mesh/propeller.dae</uri>
          </mesh>
        </geometry>
      </visual>
    </link>


    <!-- Thruster right -->
    <plugin name='gz::sim::systems::Thruster' filename='gz-sim-thruster-system'>
      <joint_name>catamaran/right_engine_propeller_joint</joint_name>
      <thrust_coefficient>0.004422</thrust_coefficient>
      <thrust_direction>0 1 0</thrust_direction>
      <fluid_density>1000</fluid_density>
      <propeller_diameter>0.2</propeller_diameter>
      <velocity_control>true</velocity_control>
      <max_thrust_cmd>1000</max_thrust_cmd>
      <!-- Naming for thrust topics. Results in:
            /catamaran/thrusters/rear_right
            /catamaran/thrusters/rear_right/ang_vel
      -->
      <namespace>catamaran</namespace>
      <topic>thrusters/rear_right</topic>
      <name>rear_right</name>
    </plugin>

    <!-- GPS -->
    <joint name='catamaran/gps_catamaran_joint' type='revolute'>
      <pose relative_to='base_link'>-0.84999999999999998 0 1.3 0 0 0</pose>
      <parent>base_link</parent>
      <child>catamaran/gps_catamaran_link</child>
      <axis>
        <xyz>0 0 1</xyz>
        <limit>
          <lower>0</lower>
          <upper>0</upper>
          <effort>1000</effort>
          <velocity>0</velocity>
        </limit>
        <dynamics>
          <spring_reference>0</spring_reference>
          <spring_stiffness>0</spring_stiffness>
        </dynamics>
      </axis>
    </joint>
    <link name='catamaran/gps_catamaran_link'>
      <pose relative_to='catamaran/gps_catamaran_joint'>0 0 0 0 0 0</pose>
      <inertial>
        <pose>0 0 0 0 0 0</pose>
        <mass>1</mass>
        <inertia>
          <ixx>0.0064580000000000002</ixx>
          <ixy>0</ixy>
          <ixz>0</ixz>
          <iyy>0.0064580000000000002</iyy>
          <iyz>0</iyz>
          <izz>0.01125</izz>
        </inertia>
      </inertial>
      <collision name='catamaran/gps_catamaran_link_fixed_joint_lump__gps_catamaran_collision_base_collision'>
        <pose>0 0 0.025000000000000001 0 0 0</pose>
        <geometry>
          <cylinder>
            <length>0.050000000000000003</length>
            <radius>0.014999999999999999</radius>
          </cylinder>
        </geometry>
      </collision>
      <collision name='catamaran/gps_catamaran_link_fixed_joint_lump__gps_catamaran_collision_antenna_collision_1'>
        <pose>0 0 0.11 0 0 0</pose>
        <geometry>
          <cylinder>
            <length>0.10000000000000001</length>
            <radius>0.14999999999999999</radius>
          </cylinder>
        </geometry>
      </collision>
      <visual name='catamaran/gps_catamaran_link_fixed_joint_lump__gps_catamaran_visual_visual'>
        <pose>0 0 0 0 0 0</pose>
        <geometry>
          <mesh>
            <scale>1 1 1</scale>
            <uri>model://gps/mesh/gps.dae</uri>
          </mesh>
        </geometry>
      </visual>
      <sensor name='navsat' type='navsat'>
        <always_on>true</always_on>
        <update_rate>20</update_rate>
      </sensor>
    </link>

    <!-- IMU -->
    <joint name='catamaran/imu_catamaran_joint' type='revolute'>
      <pose relative_to='base_link'>0.29999999999999999 -0.20000000000000001 1.3 0 0 0</pose>
      <parent>base_link</parent>
      <child>catamaran/imu_catamaran_link</child>
      <axis>
        <xyz>0 0 1</xyz>
        <limit>
          <lower>0</lower>
          <upper>0</upper>
          <effort>1000</effort>
          <velocity>0</velocity>
        </limit>
        <dynamics>
          <spring_reference>0</spring_reference>
          <spring_stiffness>0</spring_stiffness>
        </dynamics>
      </axis>
    </joint>
    <link name='catamaran/imu_catamaran_link'>
      <pose relative_to='catamaran/imu_catamaran_joint'>0 0 0 0 0 0</pose>
      <inertial>
        <pose>0 0 0 0 0 0</pose>
        <mass>0.10000000000000001</mass>
        <inertia>
          <ixx>5.4199999999999998e-06</ixx>
          <ixy>0</ixy>
          <ixz>0</ixz>
          <iyy>2.1039999999999998e-05</iyy>
          <iyz>0</iyz>
          <izz>2.6040000000000001e-05</izz>
        </inertia>
      </inertial>
      <collision name='catamaran/imu_catamaran_link_fixed_joint_lump__imu_catamaran_collision_collision'>
        <pose>0 0 0 0 0 0</pose>
        <geometry>
          <box>
            <size>0.050000000000000003 0.025000000000000001 0.0050000000000000001</size>
          </box>
        </geometry>
      </collision>
      <visual name='catamaran/imu_catamaran_link_fixed_joint_lump__imu_catamaran_visual_visual'>
        <pose>0 0 0 0 0 0</pose>
        <geometry>
          <box>
            <size>0.050000000000000003 0.025000000000000001 0.0050000000000000001</size>
          </box>
        </geometry>
        <material>
          <diffuse>1 0 0 1</diffuse>
          <ambient>1 0 0 1</ambient>
        </material>
      </visual>
      <sensor name='imu_catamaran_sensor' type='imu'>
        <update_rate>100</update_rate>
        <imu>
          <angular_velocity>
            <x>
              <noise type='gaussian'>
                <mean>0</mean>
                <stddev>0.0089999999999999993</stddev>
                <bias_mean>0.00075000000000000002</bias_mean>
                <bias_stddev>0.0050000000000000001</bias_stddev>
                <dynamic_bias_stddev>2.0000000000000002e-05</dynamic_bias_stddev>
                <dynamic_bias_correlation_time>400</dynamic_bias_correlation_time>
                <precision>0.00025000000000000001</precision>
              </noise>
            </x>
            <y>
              <noise type='gaussian'>
                <mean>0</mean>
                <stddev>0.0089999999999999993</stddev>
                <bias_mean>0.00075000000000000002</bias_mean>
                <bias_stddev>0.0050000000000000001</bias_stddev>
                <dynamic_bias_stddev>2.0000000000000002e-05</dynamic_bias_stddev>
                <dynamic_bias_correlation_time>400</dynamic_bias_correlation_time>
                <precision>0.00025000000000000001</precision>
              </noise>
            </y>
            <z>
              <noise type='gaussian'>
                <mean>0</mean>
                <stddev>0.0089999999999999993</stddev>
                <bias_mean>0.00075000000000000002</bias_mean>
                <bias_stddev>0.0050000000000000001</bias_stddev>
                <dynamic_bias_stddev>2.0000000000000002e-05</dynamic_bias_stddev>
                <dynamic_bias_correlation_time>400</dynamic_bias_correlation_time>
                <precision>0.00025000000000000001</precision>
              </noise>
            </z>
          </angular_velocity>
          <linear_acceleration>
            <x>
              <noise type='gaussian'>
                <mean>0</mean>
                <stddev>0.021000000000000001</stddev>
                <bias_mean>0.050000000000000003</bias_mean>
                <bias_stddev>0.0074999999999999997</bias_stddev>
                <dynamic_bias_stddev>0.00037500000000000001</dynamic_bias_stddev>
                <dynamic_bias_correlation_time>175</dynamic_bias_correlation_time>
                <precision>0.0050000000000000001</precision>
              </noise>
            </x>
            <y>
              <noise type='gaussian'>
                <mean>0</mean>
                <stddev>0.021000000000000001</stddev>
                <bias_mean>0.050000000000000003</bias_mean>
                <bias_stddev>0.0074999999999999997</bias_stddev>
                <dynamic_bias_stddev>0.00037500000000000001</dynamic_bias_stddev>
                <dynamic_bias_correlation_time>175</dynamic_bias_correlation_time>
                <precision>0.0050000000000000001</precision>
              </noise>
            </y>
            <z>
              <noise type='gaussian'>
                <mean>0</mean>
                <stddev>0.021000000000000001</stddev>
                <bias_mean>0.050000000000000003</bias_mean>
                <bias_stddev>0.0074999999999999997</bias_stddev>
                <dynamic_bias_stddev>0.00037500000000000001</dynamic_bias_stddev>
                <dynamic_bias_correlation_time>175</dynamic_bias_correlation_time>
                <precision>0.0050000000000000001</precision>
              </noise>
            </z>
          </linear_acceleration>
          <orientation_reference_frame>
            <localization>ENU</localization>
          </orientation_reference_frame>
        </imu>
      </sensor>
    </link>
  </model>
</sdf>
