<sdf version='1.9'>
  <model name='WAM-V'>
    <link name='wamv/base_link'>
      <inertial>
        <pose>-0.01214574898785425 -1.438345618947571e-17 0.2380566801619433 0 0 0</pose>
        <mass>247</mass>
        <inertia>
          <ixx>219.25965887314439</ixx>
          <ixy>4.3150368568427137e-17</ixy>
          <ixz>3.8758299595141699</ixz>
          <iyy>446.87655495951418</iyy>
          <iyz>-8.4574722394117186e-16</iyz>
          <izz>498.16656275303637</izz>
        </inertia>
      </inertial>
      <collision name='wamv/base_link_fixed_joint_lump__left_float_collision'>
        <pose>-0.4 1.03 0.2 0 1.570796326794897 0</pose>
        <geometry>
          <cylinder>
            <length>4</length>
            <radius>0.20000000000000001</radius>
          </cylinder>
        </geometry>
      </collision>
      <collision name='wamv/base_link_fixed_joint_lump__left_mid_float_collision_1'>
        <pose>1.85 1.03 0.3 0 1.38 0</pose>
        <geometry>
          <cylinder>
            <length>0.5</length>
            <radius>0.17000000000000001</radius>
          </cylinder>
        </geometry>
      </collision>
      <collision name='wamv/base_link_fixed_joint_lump__left_front_float_collision_2'>
        <pose>2.3 1.03 0.4 0 1.3 0</pose>
        <geometry>
          <cylinder>
            <length>0.45000000000000001</length>
            <radius>0.12</radius>
          </cylinder>
        </geometry>
      </collision>
      <collision name='wamv/base_link_fixed_joint_lump__front_left_beam_lower_collision_3'>
        <pose>0.9 0.85 1 0.78 0 0</pose>
        <geometry>
          <cylinder>
            <length>0.5</length>
            <radius>0.040000000000000001</radius>
          </cylinder>
        </geometry>
      </collision>
      <collision name='wamv/base_link_fixed_joint_lump__front_left_beam_upper_collision_4'>
        <pose>0.9 0.6 1.18 1.35 0 0</pose>
        <geometry>
          <cylinder>
            <length>0.20000000000000001</length>
            <radius>0.040000000000000001</radius>
          </cylinder>
        </geometry>
      </collision>
      <collision name='wamv/base_link_fixed_joint_lump__mid_left_beam_lower_collision_5'>
        <pose>-0.65 0.99 0.7 0.09999999999999999 0.25 0</pose>
        <geometry>
          <cylinder>
            <length>0.45000000000000001</length>
            <radius>0.029999999999999999</radius>
          </cylinder>
        </geometry>
      </collision>
      <collision name='wamv/base_link_fixed_joint_lump__mid_left_beam_medium_collision_6'>
        <pose>-0.57 0.87 1.05 0.7500000000000002 0.2500000000000001 0</pose>
        <geometry>
          <cylinder>
            <length>0.32000000000000001</length>
            <radius>0.029999999999999999</radius>
          </cylinder>
        </geometry>
      </collision>
      <collision name='wamv/base_link_fixed_joint_lump__mid_left_beam_upper_collision_7'>
        <pose>-0.55 0.65 1.17 1.35 0.2500000000000001 -1.43230569624784e-17</pose>
        <geometry>
          <cylinder>
            <length>0.29999999999999999</length>
            <radius>0.029999999999999999</radius>
          </cylinder>
        </geometry>
      </collision>
      <collision name='wamv/base_link_fixed_joint_lump__rear_left_beam_lower_collision_8'>
        <pose>-0.74 1.03 0.7 0 -0.15 0</pose>
        <geometry>
          <cylinder>
            <length>0.45000000000000001</length>
            <radius>0.029999999999999999</radius>
          </cylinder>
        </geometry>
      </collision>
      <collision name='wamv/base_link_fixed_joint_lump__rear_left_beam_medium_collision_9'>
        <pose>-0.79 0.91 1.05 0.7500000000000001 -0.15 -7.017695054745588e-18</pose>
        <geometry>
          <cylinder>
            <length>0.32000000000000001</length>
            <radius>0.029999999999999999</radius>
          </cylinder>
        </geometry>
      </collision>
      <collision name='wamv/base_link_fixed_joint_lump__rear_left_beam_upper_collision_10'>
        <pose>-0.8100000000000001 0.67 1.18 1.45 -0.15 0</pose>
        <geometry>
          <cylinder>
            <length>0.29999999999999999</length>
            <radius>0.029999999999999999</radius>
          </cylinder>
        </geometry>
      </collision>
      <collision name='wamv/base_link_fixed_joint_lump__left_joint_collision_11'>
        <pose>0.58 1.03 0.6 0 -0.5999999999999999 0</pose>
        <geometry>
          <box>
            <size>0.65 0.2 0.1</size>
          </box>
        </geometry>
      </collision>
      <collision name='wamv/base_link_fixed_joint_lump__right_float_collision_12'>
        <pose>-0.4 -1.03 0.2 0 1.570796326794897 0</pose>
        <geometry>
          <cylinder>
            <length>4</length>
            <radius>0.20000000000000001</radius>
          </cylinder>
        </geometry>
      </collision>
      <collision name='wamv/base_link_fixed_joint_lump__right_mid_float_collision_13'>
        <pose>1.85 -1.03 0.3 0 1.38 0</pose>
        <geometry>
          <cylinder>
            <length>0.5</length>
            <radius>0.17000000000000001</radius>
          </cylinder>
        </geometry>
      </collision>
      <collision name='wamv/base_link_fixed_joint_lump__right_front_float_collision_14'>
        <pose>2.3 -1.03 0.4 0 1.3 0</pose>
        <geometry>
          <cylinder>
            <length>0.45000000000000001</length>
            <radius>0.12</radius>
          </cylinder>
        </geometry>
      </collision>
      <collision name='wamv/base_link_fixed_joint_lump__front_right_beam_lower_collision_15'>
        <pose>0.9 -0.85 1 -0.78 0 0</pose>
        <geometry>
          <cylinder>
            <length>0.5</length>
            <radius>0.040000000000000001</radius>
          </cylinder>
        </geometry>
      </collision>
      <collision name='wamv/base_link_fixed_joint_lump__front_right_beam_upper_collision_16'>
        <pose>0.9 -0.6 1.18 -1.35 0 0</pose>
        <geometry>
          <cylinder>
            <length>0.20000000000000001</length>
            <radius>0.040000000000000001</radius>
          </cylinder>
        </geometry>
      </collision>
      <collision name='wamv/base_link_fixed_joint_lump__mid_right_beam_lower_collision_17'>
        <pose>-0.65 -0.99 0.7 -0.09999999999999999 0.25 0</pose>
        <geometry>
          <cylinder>
            <length>0.45000000000000001</length>
            <radius>0.029999999999999999</radius>
          </cylinder>
        </geometry>
      </collision>
      <collision name='wamv/base_link_fixed_joint_lump__mid_right_beam_medium_collision_18'>
        <pose>-0.57 -0.87 1.05 -0.7500000000000002 0.2500000000000001 0</pose>
        <geometry>
          <cylinder>
            <length>0.32000000000000001</length>
            <radius>0.029999999999999999</radius>
          </cylinder>
        </geometry>
      </collision>
      <collision name='wamv/base_link_fixed_joint_lump__mid_right_beam_upper_collision_19'>
        <pose>-0.55 -0.65 1.17 -1.35 0.2500000000000001 1.43230569624784e-17</pose>
        <geometry>
          <cylinder>
            <length>0.29999999999999999</length>
            <radius>0.029999999999999999</radius>
          </cylinder>
        </geometry>
      </collision>
      <collision name='wamv/base_link_fixed_joint_lump__rear_right_beam_lower_collision_20'>
        <pose>-0.74 -1.03 0.7 0 -0.15 0</pose>
        <geometry>
          <cylinder>
            <length>0.45000000000000001</length>
            <radius>0.029999999999999999</radius>
          </cylinder>
        </geometry>
      </collision>
      <collision name='wamv/base_link_fixed_joint_lump__rear_right_beam_medium_collision_21'>
        <pose>-0.79 -0.91 1.05 -0.7500000000000001 -0.15 7.017695054745588e-18</pose>
        <geometry>
          <cylinder>
            <length>0.32000000000000001</length>
            <radius>0.029999999999999999</radius>
          </cylinder>
        </geometry>
      </collision>
      <collision name='wamv/base_link_fixed_joint_lump__rear_right_beam_upper_collision_22'>
        <pose>-0.8100000000000001 -0.67 1.18 -1.45 -0.15 0</pose>
        <geometry>
          <cylinder>
            <length>0.29999999999999999</length>
            <radius>0.029999999999999999</radius>
          </cylinder>
        </geometry>
      </collision>
      <collision name='wamv/base_link_fixed_joint_lump__right_joint_collision_23'>
        <pose>0.58 -1.03 0.6 0 -0.5999999999999999 0</pose>
        <geometry>
          <box>
            <size>0.65 0.2 0.1</size>
          </box>
        </geometry>
      </collision>
      <collision name='wamv/base_link_fixed_joint_lump__top_base_collision_24'>
        <pose>0 0 1.25 0 0 0</pose>
        <geometry>
          <box>
            <size>1.85 1 0.1</size>
          </box>
        </geometry>
      </collision>
      <collision name='wamv/base_link_fixed_joint_lump__cpu_case_1_collision_collision_25'>
        <pose>0.035 0 1.53 0 0 0</pose>
        <geometry>
          <box>
            <size>0.595 0.83 0.47</size>
          </box>
        </geometry>
      </collision>
      <collision name='wamv/base_link_fixed_joint_lump__cpu_case_2_collision_collision_26'>
        <pose>-0.45 0 1.438 0 0 0</pose>
        <geometry>
          <box>
            <size>0.375 0.64 0.28</size>
          </box>
        </geometry>
      </collision>
      <collision name='wamv/base_link_fixed_joint_lump__left_battery_collision_collision_27'>
        <pose>0 1 0.6 0 0 0</pose>
        <geometry>
          <box>
            <size>0.6 0.4 0.31</size>
          </box>
        </geometry>
      </collision>
      <collision name='wamv/base_link_fixed_joint_lump__right_battery_collision_collision_28'>
        <pose>0 -1 0.6 0 0 0</pose>
        <geometry>
          <box>
            <size>0.6 0.4 0.31</size>
          </box>
        </geometry>
      </collision>
      <visual name='wamv/base_link_visual'>
        <pose>0 0 0 0 0 0</pose>
        <geometry>
          <mesh>
            <scale>1 1 1</scale>
            <uri>model://wamv_description/models/WAM-V-Base/mesh/WAM-V-Base.dae</uri>
          </mesh>
        </geometry>
        <material>
          <diffuse>1 1 1 1</diffuse>
          <specular>1 1 1 1</specular>
          <pbr>
            <metal>
              <albedo_map>model://wamv_description/models/WAM-V-Base/mesh/WAM-V_Albedo.png</albedo_map>
              <normal_map>model://wamv_description/models/WAM-V-Base/mesh/WAM-V_Normal.png</normal_map>
              <roughness_map>model://wamv_description/models/WAM-V-Base/mesh/WAM-V_Roughness.png</roughness_map>
              <metalness_map>model://wamv_description/models/WAM-V-Base/mesh/WAM-V_Metalness.png</metalness_map>
            </metal>
          </pbr>
        </material>
      </visual>
      <visual name='wamv/base_link_fixed_joint_lump__wamv/cpu_cases_link_visual_1'>
        <pose>-0.077 0 0 0 0 0</pose>
        <geometry>
          <mesh>
            <scale>1 1 1</scale>
            <uri>model://vrx_gazebo/models/cpu_cases/mesh/cpu_cases.dae</uri>
          </mesh>
        </geometry>
        <material>
          <diffuse>1 1 1 1</diffuse>
          <specular>1 1 1 1</specular>
          <pbr>
            <metal>
              <albedo_map>model://vrx_gazebo/models/cpu_cases/mesh/cpu_cases_Albedo.png</albedo_map>
              <normal_map>model://vrx_gazebo/models/cpu_cases/mesh/cpu_cases_Normal.png</normal_map>
              <roughness_map>model://vrx_gazebo/models/cpu_cases/mesh/cpu_cases_Roughness.png</roughness_map>
              <metalness_map>model://vrx_gazebo/models/cpu_cases/mesh/cpu_cases_Metalness.png</metalness_map>
            </metal>
          </pbr>
        </material>
      </visual>
      <visual name='wamv/base_link_fixed_joint_lump__wamv/left_battery_link_visual_2'>
        <pose>0 -0.03000000000000003 0 0 0 0</pose>
        <geometry>
          <mesh>
            <scale>1 1 1</scale>
            <uri>model://vrx_gazebo/models/battery/mesh/battery.dae</uri>
          </mesh>
        </geometry>
        <material>
          <diffuse>1 1 1 1</diffuse>
          <specular>1 1 1 1</specular>
          <pbr>
            <metal>
              <albedo_map>model://vrx_gazebo/models/battery/mesh/battery_Albedo.png</albedo_map>
              <normal_map>model://vrx_gazebo/models/battery/mesh/battery_Normal.png</normal_map>
              <roughness_map>model://vrx_gazebo/models/battery/mesh/battery_Roughness.png</roughness_map>
              <metalness_map>model://vrx_gazebo/models/battery/mesh/battery_Metalness.png</metalness_map>
            </metal>
          </pbr>
        </material>
      </visual>
      <visual name='wamv/base_link_fixed_joint_lump__wamv/right_battery_link_visual_3'>
        <pose>0 -2.03 0 0 0 0</pose>
        <geometry>
          <mesh>
            <scale>1 1 1</scale>
            <uri>model://vrx_gazebo/models/battery/mesh/battery.dae</uri>
          </mesh>
        </geometry>
        <material>
          <diffuse>1 1 1 1</diffuse>
          <specular>1 1 1 1</specular>
          <pbr>
            <metal>
              <albedo_map>model://vrx_gazebo/models/battery/mesh/battery_Albedo.png</albedo_map>
              <normal_map>model://vrx_gazebo/models/battery/mesh/battery_Normal.png</normal_map>
              <roughness_map>model://vrx_gazebo/models/battery/mesh/battery_Roughness.png</roughness_map>
              <metalness_map>model://vrx_gazebo/models/battery/mesh/battery_Metalness.png</metalness_map>
            </metal>
          </pbr>
        </material>
      </visual>
      <sensor name='contact_sensor' type='contact'>
        <contact>
          <collision>wamv/base_link_fixed_joint_lump__top_base_collision_24</collision>
          <collision>wamv/base_link_fixed_joint_lump__left_float_collision</collision>
          <collision>wamv/base_link_fixed_joint_lump__left_mid_float_collision_1</collision>
          <collision>wamv/base_link_fixed_joint_lump__left_front_float_collision_2</collision>
          <collision>wamv/base_link_fixed_joint_lump__right_float_collision_12</collision>
          <collision>wamv/base_link_fixed_joint_lump__right_mid_float_collision_13</collision>
          <collision>wamv/base_link_fixed_joint_lump__right_front_float_collision_14</collision>
          <topic>/vrx/contacts</topic>
        </contact>
        <always_on>true</always_on>
        <update_rate>5</update_rate>
      </sensor>
    </link>
    <joint name='wamv/left_chassis_engine_joint' type='revolute'>
      <pose relative_to='wamv/base_link'>-2.373776 1.027135 0.318237 0 0 0</pose>
      <parent>wamv/base_link</parent>
      <child>wamv/left_engine_link</child>
      <axis>
        <xyz>0 0 1</xyz>
        <limit>
          <lower>-3.1415926535897931</lower>
          <upper>3.1415926535897931</upper>
          <effort>10</effort>
          <velocity>10</velocity>
        </limit>
        <dynamics>
          <spring_reference>0</spring_reference>
          <spring_stiffness>0</spring_stiffness>
        </dynamics>
      </axis>
    </joint>
    <link name='wamv/left_engine_link'>
      <pose relative_to='wamv/left_chassis_engine_joint'>0 0 0 0 0 0</pose>
      <inertial>
        <pose>0 0 0 0 0 0</pose>
        <mass>15</mass>
        <inertia>
          <ixx>0.88924499999999995</ixx>
          <ixy>0</ixy>
          <ixz>0</ixz>
          <iyy>0.91112499999999996</iyy>
          <iyz>0</iyz>
          <izz>0.078125</izz>
        </inertia>
      </inertial>
      <collision name='wamv/left_engine_link_fixed_joint_lump__left_engine_vertical_axis_collision_collision'>
        <pose>-0.16 0 -0.24 0 0 0</pose>
        <geometry>
          <box>
            <size>0.2 0.15 0.83</size>
          </box>
        </geometry>
      </collision>
      <collision name='wamv/left_engine_link_fixed_joint_lump__left_engine_rear_end_collision_collision_1'>
        <pose>-0.34 0 0.12 0 0 0</pose>
        <geometry>
          <box>
            <size>0.12 0.15 0.12</size>
          </box>
        </geometry>
      </collision>
      <visual name='wamv/left_engine_link_visual'>
        <pose>0 0 0 0 0 0</pose>
        <geometry>
          <mesh>
            <scale>1 1 1</scale>
            <uri>model://wamv_description/models/engine/mesh/engine.dae</uri>
          </mesh>
        </geometry>
      </visual>
    </link>
    <joint name='wamv/left_engine_propeller_joint' type='revolute'>
      <pose relative_to='wamv/left_engine_link'>-0.278156 0 -0.509371 0 0 0</pose>
      <parent>wamv/left_engine_link</parent>
      <child>wamv/left_propeller_link</child>
      <axis>
        <xyz>1 0 0</xyz>
        <limit>
          <effort>100</effort>
          <velocity>100</velocity>
          <lower>-10000000000000000</lower>
          <upper>10000000000000000</upper>
        </limit>
        <dynamics>
          <damping>0.050000000000000003</damping>
          <friction>0.050000000000000003</friction>
          <spring_reference>0</spring_reference>
          <spring_stiffness>0</spring_stiffness>
        </dynamics>
      </axis>
    </joint>
    <link name='wamv/left_propeller_link'>
      <pose relative_to='wamv/left_engine_propeller_joint'>0 0 0 0 0 0</pose>
      <inertial>
        <pose>0 0 0 0 0 0</pose>
        <mass>0.5</mass>
        <inertia>
          <ixx>0.0085450000000000005</ixx>
          <ixy>0</ixy>
          <ixz>0</ixz>
          <iyy>0.0085450000000000005</iyy>
          <iyz>0</iyz>
          <izz>0.0144</izz>
        </inertia>
      </inertial>
      <collision name='wamv/left_propeller_link_fixed_joint_lump__left_propeller_collision_collision'>
        <pose>-0.08 0 0 0 1.570796326794897 0</pose>
        <geometry>
          <cylinder>
            <length>0.17999999999999999</length>
            <radius>0.23999999999999999</radius>
          </cylinder>
        </geometry>
      </collision>
      <visual name='wamv/left_propeller_link_visual'>
        <pose>0 0 0 0 0 0</pose>
        <geometry>
          <mesh>
            <scale>1 1 1</scale>
            <uri>model://wamv_description/models/propeller/mesh/propeller.dae</uri>
          </mesh>
        </geometry>
      </visual>
    </link>
    <joint name='wamv/right_chassis_engine_joint' type='revolute'>
      <pose relative_to='wamv/base_link'>-2.373776 -1.027135 0.318237 0 0 0</pose>
      <parent>wamv/base_link</parent>
      <child>wamv/right_engine_link</child>
      <axis>
        <xyz>0 0 1</xyz>
        <limit>
          <lower>-3.1415926535897931</lower>
          <upper>3.1415926535897931</upper>
          <effort>10</effort>
          <velocity>10</velocity>
        </limit>
        <dynamics>
          <spring_reference>0</spring_reference>
          <spring_stiffness>0</spring_stiffness>
        </dynamics>
      </axis>
    </joint>
    <link name='wamv/right_engine_link'>
      <pose relative_to='wamv/right_chassis_engine_joint'>0 0 0 0 0 0</pose>
      <inertial>
        <pose>0 0 0 0 0 0</pose>
        <mass>15</mass>
        <inertia>
          <ixx>0.88924499999999995</ixx>
          <ixy>0</ixy>
          <ixz>0</ixz>
          <iyy>0.91112499999999996</iyy>
          <iyz>0</iyz>
          <izz>0.078125</izz>
        </inertia>
      </inertial>
      <collision name='wamv/right_engine_link_fixed_joint_lump__right_engine_vertical_axis_collision_collision'>
        <pose>-0.16 0 -0.24 0 0 0</pose>
        <geometry>
          <box>
            <size>0.2 0.15 0.83</size>
          </box>
        </geometry>
      </collision>
      <collision name='wamv/right_engine_link_fixed_joint_lump__right_engine_rear_end_collision_collision_1'>
        <pose>-0.34 0 0.12 0 0 0</pose>
        <geometry>
          <box>
            <size>0.12 0.15 0.12</size>
          </box>
        </geometry>
      </collision>
      <visual name='wamv/right_engine_link_visual'>
        <pose>0 0 0 0 0 0</pose>
        <geometry>
          <mesh>
            <scale>1 1 1</scale>
            <uri>model://wamv_description/models/engine/mesh/engine.dae</uri>
          </mesh>
        </geometry>
      </visual>
    </link>
    <joint name='wamv/right_engine_propeller_joint' type='revolute'>
      <pose relative_to='wamv/right_engine_link'>-0.278156 0 -0.509371 0 0 0</pose>
      <parent>wamv/right_engine_link</parent>
      <child>wamv/right_propeller_link</child>
      <axis>
        <xyz>1 0 0</xyz>
        <limit>
          <effort>100</effort>
          <velocity>100</velocity>
          <lower>-10000000000000000</lower>
          <upper>10000000000000000</upper>
        </limit>
        <dynamics>
          <damping>0.050000000000000003</damping>
          <friction>0.050000000000000003</friction>
          <spring_reference>0</spring_reference>
          <spring_stiffness>0</spring_stiffness>
        </dynamics>
      </axis>
    </joint>
    <link name='wamv/right_propeller_link'>
      <pose relative_to='wamv/right_engine_propeller_joint'>0 0 0 0 0 0</pose>
      <inertial>
        <pose>0 0 0 0 0 0</pose>
        <mass>0.5</mass>
        <inertia>
          <ixx>0.0085450000000000005</ixx>
          <ixy>0</ixy>
          <ixz>0</ixz>
          <iyy>0.0085450000000000005</iyy>
          <iyz>0</iyz>
          <izz>0.0144</izz>
        </inertia>
      </inertial>
      <collision name='wamv/right_propeller_link_fixed_joint_lump__right_propeller_collision_collision'>
        <pose>-0.08 0 0 0 1.570796326794897 0</pose>
        <geometry>
          <cylinder>
            <length>0.17999999999999999</length>
            <radius>0.23999999999999999</radius>
          </cylinder>
        </geometry>
      </collision>
      <visual name='wamv/right_propeller_link_visual'>
        <pose>0 0 0 0 0 0</pose>
        <geometry>
          <mesh>
            <scale>1 1 1</scale>
            <uri>model://wamv_description/models/propeller/mesh/propeller.dae</uri>
          </mesh>
        </geometry>
      </visual>
    </link>
    <enable_wind>true</enable_wind>
    <plugin name='gz::sim::systems::Thruster' filename='gz-sim-thruster-system'>
      <joint_name>wamv/left_engine_propeller_joint</joint_name>
      <thrust_coefficient>0.004422</thrust_coefficient>
      <fluid_density>1000</fluid_density>
      <propeller_diameter>0.2</propeller_diameter>
      <velocity_control>true</velocity_control>
      <max_thrust_cmd>2353.53383667818</max_thrust_cmd>
      <namespace>wamv</namespace>
      <topic>thrusters/left/thrust</topic>
      <name>left</name>
    </plugin>
    <plugin name='gz::sim::systems::JointPositionController' filename='gz-sim-joint-position-controller-system'>
      <joint_name>wamv/left_chassis_engine_joint</joint_name>
      <use_velocity_commands>true</use_velocity_commands>
      <topic>wamv/thrusters/left/pos</topic>
      <name>left</name>
    </plugin>
    <plugin name='gz::sim::systems::Thruster' filename='gz-sim-thruster-system'>
      <joint_name>wamv/right_engine_propeller_joint</joint_name>
      <thrust_coefficient>0.004422</thrust_coefficient>
      <fluid_density>1000</fluid_density>
      <propeller_diameter>0.2</propeller_diameter>
      <velocity_control>true</velocity_control>
      <max_thrust_cmd>2353.53383667818</max_thrust_cmd>
      <namespace>wamv</namespace>
      <topic>thrusters/right/thrust</topic>
      <name>right</name>
    </plugin>
    <plugin name='gz::sim::systems::JointPositionController' filename='gz-sim-joint-position-controller-system'>
      <joint_name>wamv/right_chassis_engine_joint</joint_name>
      <use_velocity_commands>true</use_velocity_commands>
      <topic>wamv/thrusters/right/pos</topic>
      <name>right</name>
    </plugin>
    <plugin name='vrx::Surface' filename='libSurface.so'>
      <link_name>wamv/base_link</link_name>
      <hull_length>4.9</hull_length>
      <hull_radius>0.213</hull_radius>
      <fluid_level>0</fluid_level>
      <points>
        <point>0.6 1.03 0</point>
        <point>-1.4 1.03 0</point>
      </points>
      <wavefield>
        <topic>/vrx/wavefield/parameters</topic>
      </wavefield>
    </plugin>
    <plugin name='vrx::Surface' filename='libSurface.so'>
      <link_name>wamv/base_link</link_name>
      <hull_length>4.9</hull_length>
      <hull_radius>0.213</hull_radius>
      <fluid_level>0</fluid_level>
      <points>
        <point>0.6 -1.03 0</point>
        <point>-1.4 -1.03 0</point>
      </points>
      <wavefield>
        <topic>/vrx/wavefield/parameters</topic>
      </wavefield>
    </plugin>
    <plugin name='vrx::SimpleHydrodynamics' filename='libSimpleHydrodynamics.so'>
      <link_name>wamv/base_link</link_name>
      <xDotU>0.0</xDotU>
      <yDotV>0.0</yDotV>
      <nDotR>0.0</nDotR>
      <xU>100.0</xU>
      <xUU>150.0</xUU>
      <yV>100.0</yV>
      <yVV>100.0</yVV>
      <zW>500.0</zW>
      <kP>300.0</kP>
      <kPP>600.0</kPP>
      <mQ>900.0</mQ>
      <mQQ>900.0</mQQ>
      <nR>800.0</nR>
      <nRR>800.0</nRR>
    </plugin>
    <plugin name='gz::sim::systems::DetachableJoint' filename='gz-sim-detachable-joint-system'>
      <parent_link>wamv/base_link</parent_link>
      <child_model>platform</child_model>
      <child_link>dummy_upper</child_link>
      <topic>/vrx/release</topic>
      <suppress_child_warning>true</suppress_child_warning>
    </plugin>
    <plugin name='gz::sim::systems::PosePublisher' filename='libgz-sim-pose-publisher-system.so'>
      <publish_link_pose>false</publish_link_pose>
      <publish_sensor_pose>true</publish_sensor_pose>
      <publish_collision_pose>false</publish_collision_pose>
      <publish_visual_pose>false</publish_visual_pose>
      <publish_nested_model_pose>false</publish_nested_model_pose>
      <publish_model_pose>false</publish_model_pose>
      <use_pose_vector_msg>true</use_pose_vector_msg>
      <static_publisher>false</static_publisher>
      <static_update_frequency>1</static_update_frequency>
    </plugin>
    <plugin name='gz::sim::systems::JointStatePublisher' filename='gz-sim-joint-state-publisher-system'/>
    <frame name='wamv/chasis_cpu_cases_joint' attached_to='wamv/base_link'>
      <pose>-0.15 0 1.53 0 -0 0</pose>
    </frame>
    <frame name='wamv/cpu_cases_link' attached_to='wamv/chasis_cpu_cases_joint'/>
    <frame name='wamv/left_chasis_battery_joint' attached_to='wamv/base_link'>
      <pose>0 1 0.45 0 -0 0</pose>
    </frame>
    <frame name='wamv/left_battery_link' attached_to='wamv/left_chasis_battery_joint'/>
    <frame name='wamv/right_chasis_battery_joint' attached_to='wamv/base_link'>
      <pose>0 -1 0.45 0 -0 0</pose>
    </frame>
    <frame name='wamv/right_battery_link' attached_to='wamv/right_chasis_battery_joint'/>
  </model>
</sdf>
